<mujoco model="panda_hand">
    <size njmax="500" nconmax="100" />
    <asset>
        <mesh name="hand" file="meshes/panda_gripper/hand.stl" />
        <mesh name="pad" file="meshes/panda_gripper/pad.stl"  scale="0.003 0.003 0.003"/>  
        <mesh name="hand_vis" file="meshes/panda_gripper/hand_vis.stl" />
        <mesh name="finger" file="meshes/panda_gripper/finger.stl" />
        <mesh name="finger_vis" file="meshes/panda_gripper/finger_vis.stl" />
        <mesh name="finger_vis2" file="meshes/panda_gripper/finger_longer.stl" />

    </asset>

    <actuator>
        <position ctrllimited="true" ctrlrange="0 0.04" joint="finger_joint1" kp="1000000" name="gripper_joint1" forcelimited="true" forcerange="-20 20"/>
        <position ctrllimited="true" ctrlrange="-0.04 0" joint="finger_joint2" kp="1000000" name="gripper_joint2" forcelimited="true" forcerange="-20 20"/>
    </actuator>

    <worldbody>
      <body name="right_gripper" pos="0 0 -0.018">

            <site name="ft_frame" pos="0 0 0" size="0.01 0.01 0.01" rgba="1 0 0 1" type="sphere" group="1"></site>

            <inertial pos="0 0 0.17" quat="0.707107 0.707107 0 0" mass="0.0" diaginertia="0.09 0.07 0.05" />
            <!--<geom type="mesh" contype="0" conaffinity="0" group="1" mesh="link7" /> -->
      <!--       <geom pos="0 0 0.107" quat="0.92388 0 0 -0.382683" type="mesh" contype="0" conaffinity="0" group="1" mesh="hand" name="hand_collision"/> -->

                  <!--<geom type="mesh" contype="0" conaffinity="0" group="1" mesh="link7" /> -->
            <geom pos="0 0 0." quat="0.707107 0 0 0.707" type="mesh" contype="0" conaffinity="0" group="1" mesh="hand_vis" name="hand_visual" rgba="1 1 1 1"/>


            <geom pos="0 0 0." quat="0.707107 0 0 0.707" type="mesh" mesh="hand"  group="0" name="hand_collision"/>

            <!-- This site was added for visualization. -->
            <site name="grip_site" pos="0 0 0.1050" size="0.01 0.01 0.01" rgba="1 0 0 1" type="sphere" group="1"/>
            <!-- This site was added for visualization. -->
            <site name="grip_site_cylinder" pos="0 0 0.1399" size="0.005 10" rgba="0 1 0 0.3" type="cylinder" group="1"/>

            <body name="leftfinger" pos="0 0 0.0524" quat="0.707107 0 0 0.70">
                <inertial pos="0 0 0.05" mass="0.1" diaginertia="0.01 0.01 0.005" />
                <joint name="finger_joint1" pos="0 0 0" axis="0 1 0" type="slide" limited="true" range="0.0 0.04" damping="100"/>
                <geom quat="0.707107 0.707107 0 0" type="mesh" contype="0" conaffinity="0" group="1" mesh="finger_vis" name="finger1_visual"/>

                <!-- left finger tactile -->
                <body name="touch_l1_body" pos="0.002 -0.0035 0.0536"  >
                <site name="touch_l1" type="box" size="0.001 0.001 0.001" rgba="0 0.5 0.5 0.33"/>
                <!-- <geom type="box" pos="0.001 -0.0035 0.0536" size=".001 .005 .005" rgba="0 .8 .6 0.5" contype="0" conaffinity="0"/> -->
                <geom type="mesh" mesh="pad"  group="1" name="pad1"/>
                </body>

                <body name="touch_l2_body" pos="0.006 -0.0035 0.0536"  >
                <site name="touch_l2" type="box" size="0.001 0.001 0.001" rgba="0 0.5 0.5 0.33"/>
                <geom type="mesh" mesh="pad"  group="1" name="pad2"/>
                </body>

                <body name="touch_l3_body" pos="0.010 -0.0035 0.0536"  >
                <site name="touch_l3" type="box" size="0.001 0.001 0.001" rgba="0 0.5 0.5 0.33"/>
                <geom type="mesh" mesh="pad"  group="1" name="pad3"/>
                </body>

                <body name="touch_l4_body" pos="-0.002 -0.0035 0.0536"  >
                <site name="touch_l4" type="box" size="0.001 0.001 0.001" rgba="0 0.5 0.5 0.33"/>
                <geom type="mesh" mesh="pad"  group="1" name="pad4"/>
                </body>

                <body name="touch_l5_body" pos="-0.006 -0.0035 0.0536"  >
                <site name="touch_l5" type="box" size="0.001 0.001 0.001" rgba="0 0.5 0.5 0.33"/>
                <geom type="mesh" mesh="pad"  group="1" name="pad5"/>
                </body>

                <body name="touch_l6_body" pos="-0.010 -0.0035 0.0536"  >
                <site name="touch_l6" type="box" size="0.001 0.001 0.001" rgba="0 0.5 0.5 0.33"/>
                <geom type="mesh" mesh="pad"  group="1" name="pad6"/>
                </body>

                <body name="touch_l7_body" pos="0.002 -0.0035 0.0436"  >
                <site name="touch_l7" type="box" size="0.001 0.001 0.001" rgba="0 0.5 0.5 0.33"/>
                <geom type="mesh" mesh="pad"  group="1" name="pad7"/>
                </body>

                <body name="touch_l8_body" pos="0.006 -0.0035 0.0436"  >
                <site name="touch_l8" type="box" size="0.001 0.001 0.001" rgba="0 0.5 0.5 0.33"/>
                <geom type="mesh" mesh="pad"  group="1" name="pad8"/>
                </body>

                <body name="touch_l9_body" pos="0.010 -0.0035 0.0436"  >
                <site name="touch_l9" type="box" size="0.001 0.001 0.001" rgba="0 0.5 0.5 0.33"/>
                <geom type="mesh" mesh="pad"  group="1" name="pad9"/>
                </body>

                <body name="touch_l10_body" pos="-0.002 -0.0035 0.0436"  >
                <site name="touch_l10" type="box" size="0.001 0.001 0.001" rgba="0 0.5 0.5 0.33"/>
                <geom type="mesh" mesh="pad"  group="1" name="pad10"/>
                </body>

                <body name="touch_l11_body" pos="-0.006 -0.0035 0.0436"  >
                <site name="touch_l11" type="box" size="0.001 0.001 0.001" rgba="0 0.5 0.5 0.33"/>
                <geom type="mesh" mesh="pad"  group="1" name="pad11"/>
                </body>

                <body name="touch_l12_body" pos="-0.010 -0.0035 0.0436"  >
                <site name="touch_l12" type="box" size="0.001 0.001 0.001" rgba="0 0.5 0.5 0.33"/>
                <geom type="mesh" mesh="pad"  group="1" name="pad12"/>
                </body>

                <body name="touch_l13_body" pos="0.002 -0.0035 0.0336"  >
                <site name="touch_l13" type="box" size="0.001 0.001 0.001" rgba="0 0.5 0.5 0.33"/>
                <geom type="mesh" mesh="pad"  group="1" name="pad13"/>
                </body>

                <body name="touch_l14_body" pos="0.006 -0.0035 0.0336"  >
                <site name="touch_l14" type="box" size="0.001 0.001 0.001" rgba="0 0.5 0.5 0.33"/>
                <geom type="mesh" mesh="pad"  group="1" name="pad14"/>
                </body>

                <body name="touch_l15_body" pos="0.010 -0.0035 0.0336"  >
                <site name="touch_l15" type="box" size="0.001 0.001 0.001" rgba="0 0.5 0.5 0.33"/>
                <geom type="mesh" mesh="pad"  group="1" name="pad15"/>
                </body>

                <body name="touch_l16_body" pos="-0.002 -0.0035 0.0336"  >
                <site name="touch_l16" type="box" size="0.001 0.001 0.001" rgba="0 0.5 0.5 0.33"/>
                <geom type="mesh" mesh="pad"  group="1" name="pad16"/>
                </body>

                <body name="touch_l17_body" pos="-0.006 -0.0035 0.0336"  >
                <site name="touch_l17" type="box" size="0.001 0.001 0.001" rgba="0 0.5 0.5 0.33"/>
                <geom type="mesh" mesh="pad"  group="1" name="pad17"/>
                </body>

                <body name="touch_l18_body" pos="-0.010 -0.0035 0.0336"  >
                <site name="touch_l18" type="box" size="0.001 0.001 0.001" rgba="0 0.5 0.5 0.33"/>
                <geom type="mesh" mesh="pad"  group="1" name="pad18"/>
                </body>

                <!-- <site name="touch_l2" type="box" pos="0.006 -0.0035 0.0536" size="0.001 0.001 0.001" rgba="0 0.5 0.5 0.33"/>
                <site name="touch_l3" type="box" pos="0.010 -0.0035 0.0536" size="0.001 0.001 0.001" rgba="0 0.5 0.5 0.33"/>
                <site name="touch_l4" type="box" pos="-0.002 -0.0035 0.0536" size="0.001 0.001 0.001" rgba="0 0.5 0.5 0.33"/>
                <site name="touch_l5" type="box" pos="-0.006 -0.0035 0.0536" size="0.001 0.001 0.001" rgba="0 0.5 0.5 0.33"/>
                <site name="touch_l6" type="box" pos="-0.010 -0.0035 0.0536" size="0.001 0.001 0.001" rgba="0 0.5 0.5 0.33"/>
                <site name="touch_l7" type="box" pos="0.002 -0.0035 0.0436" size="0.001 0.001 0.001" rgba="0 0.5 0.5 0.33"/> -->
                <!-- <site name="touch_l8" type="box" pos="0.006 -0.0035 0.0436" size="0.001 0.001 0.001" rgba="0 0.5 0.5 0.33"/>
                <site name="touch_l9" type="box" pos="0.010 -0.0035 0.0436" size="0.001 0.001 0.001" rgba="0 0.5 0.5 0.33"/>
                <site name="touch_l10" type="box" pos="-0.002 -0.0035 0.0436" size="0.001 0.001 0.001" rgba="0 0.5 0.5 0.33"/>
                <site name="touch_l11" type="box" pos="-0.006 -0.0035 0.0436" size="0.001 0.001 0.001" rgba="0 0.5 0.5 0.33"/>
                <site name="touch_l12" type="box" pos="-0.010 -0.0035 0.0436" size="0.001 0.001 0.001" rgba="0 0.5 0.5 0.33"/> -->
                <!-- <site name="touch_l13" type="box" pos="0.002 -0.0035 0.0336" size="0.001 0.001 0.001" rgba="0 0.5 0.5 0.33"/>
                <site name="touch_l14" type="box" pos="0.006 -0.0035 0.0336" size="0.001 0.001 0.001" rgba="0 0.5 0.5 0.33"/>
                <site name="touch_l15" type="box" pos="0.010 -0.0035 0.0336" size="0.001 0.001 0.001" rgba="0 0.5 0.5 0.33"/>
                <site name="touch_l16" type="box" pos="-0.002 -0.0035 0.0336" size="0.001 0.001 0.001" rgba="0 0.5 0.5 0.33"/>
                <site name="touch_l17" type="box" pos="-0.006 -0.0035 0.0336" size="0.001 0.001 0.001" rgba="0 0.5 0.5 0.33"/> -->
                <!-- <site name="touch_l18" type="box" pos="-0.010 -0.0035 0.0336" size="0.001 0.001 0.001" rgba="0 0.5 0.5 0.33"/> -->


                <!-- <geom type="mesh" mesh="finger"  solimp="0.9 0.95 0.005" solmix="10000" solref="0.05 1"/> -->
                <!-- <geom type="mesh" mesh="fingerc" solimp="0.9 0.95 0.005" solmix="10000" solref="0.05 1"/> -->
                <!-- <geom type="mesh" mesh="fingerb" solimp="0.9 0.95 0.005" solmix="10000" solref="0.05 1"/> -->
                <geom type="mesh" conaffinity="1" contype="0" solref="0.02 1" friction="1 0 0" condim="4" mesh="finger" name="finger1_collision"/>
                <body name="finger_joint1_tip" pos="0 0.0085 0.056">
                    <inertial pos="0 0 0" quat="0 0 0 1" mass="0.01" diaginertia="0.01 0.01 0.01" />
                    <geom size="0.008 0.004 0.008" pos="0 -0.005 -0.015" quat="0 0 0 1" type="box" solref="0.01 0.5" friction = "1 0 0" conaffinity="1" contype="1" name="finger1_tip_collision"/>
                </body>
            </body>
            <body name="rightfinger" pos="0 0 0.0524" quat="0.707107 0 0 0.70">
                <inertial pos="0 0 0.05" mass="0.1" diaginertia="0.01 0.01 0.005" />
                <joint name="finger_joint2" pos="0 0 0" axis="0 1 0" type="slide" limited="true" range="-0.04 0.0" damping="100"/>
                <geom quat="0 0 0.707107 0.707107" type="mesh" contype="0" conaffinity="0" group="1" mesh="finger_vis" name="finger2_visual"/>

                <!-- <geom quat="0 0 0 1" type="mesh" mesh="finger"  solimp="0.9 0.95 0.005" solmix="10000" solref="0.05 1"/> -->
                <!-- <geom quat="0 0 0 1" type="mesh" mesh="fingerb" solimp="0.9 0.95 0.005" solmix="10000" solref="0.05 1"/> -->
                <!-- <geom quat="0 0 0 1" type="mesh" mesh="fingerc" solimp="0.9 0.95 0.005" solmix="10000" solref="0.05 1"/> -->
                <geom quat="0 0 0 1" type="mesh" conaffinity="1" contype="0" solref="0.02 1" friction="1 0 0" condim="4" mesh="finger" name="finger2_collision"/>
                <body name="finger_joint2_tip" pos="0 -0.0085 0.056">
                    <inertial pos="0 0 0" quat="0 0 0 1" mass="0.01" diaginertia="0.01 0.01 0.01" />
                    <geom size="0.008 0.004 0.008" pos="0 0.005 -0.015" quat="0 0 0 1" type="box" solref="0.01 0.5" friction = "1 0 0" conaffinity="1" contype="1" name="finger2_tip_collision"/>
                </body>
            </body>
        </body>
    </worldbody>

    <sensor>
        <force name="force_ee" site="ft_frame"/>
        <torque name="torque_ee" site="ft_frame"/>

        <!-- <force name="touch_l1" site="touch_l1"></force>
        <force name="touch_l2" site="touch_l2"></force>
        <force name="touch_l3" site="touch_l3"></force>
        <force name="touch_l4" site="touch_l4"></force>
        <force name="touch_l5" site="touch_l5"></force>
        <force name="touch_l6" site="touch_l6"></force>
        <force name="touch_l7" site="touch_l7"></force>
        <force name="touch_l8" site="touch_l8"></force>
        <force name="touch_l9" site="touch_l9"></force>
        <force name="touch_l10" site="touch_l10"></force>
        <force name="touch_l11" site="touch_l11"></force>
        <force name="touch_l12" site="touch_l12"></force>
        <force name="touch_l13" site="touch_l13"></force>
        <force name="touch_l14" site="touch_l14"></force>
        <force name="touch_l15" site="touch_l15"></force>
        <force name="touch_l16" site="touch_l16"></force>
        <force name="touch_l17" site="touch_l17"></force>
        <force name="touch_l18" site="touch_l18"></force> -->

        <touch name="touch_l1" site="touch_l1"></touch>
        <touch name="touch_l2" site="touch_l2"></touch>
        <touch name="touch_l3" site="touch_l3"></touch>
        <touch name="touch_l4" site="touch_l4"></touch>
        <touch name="touch_l5" site="touch_l5"></touch>
        <touch name="touch_l6" site="touch_l6"></touch>
        <touch name="touch_l7" site="touch_l7"></touch>
        <touch name="touch_l8" site="touch_l8"></touch>
        <touch name="touch_l9" site="touch_l9"></touch>
        <touch name="touch_l10" site="touch_l10"></touch>
        <touch name="touch_l11" site="touch_l11"></touch>
        <touch name="touch_l12" site="touch_l12"></touch>
        <touch name="touch_l13" site="touch_l13"></touch>
        <touch name="touch_l14" site="touch_l14"></touch>
        <touch name="touch_l15" site="touch_l15"></touch>
        <touch name="touch_l16" site="touch_l16"></touch>
        <touch name="touch_l17" site="touch_l17"></touch>
        <touch name="touch_l18" site="touch_l18"></touch>

    </sensor>
</mujoco>
